Workbook

Sheet Ventas Q1 2026
A1: Fecha | B1: N° Factura | C1: Cód. Cliente | D1: Cliente | E1: Tipo Cliente | F1: Ciudad | G1: Segmento | H1: Cód. Vendedor | I1: Vendedor | J1: Zona | K1: SKU | L1: Producto | M1: Línea | N1: Categoría | O1: Cantidad | P1: Unidad | Q1: Precio Unit. (COP) | R1: % Descuento | S1: Subtotal (COP) | T1: Descuento (COP) | U1: Total Venta (COP) | V1: Canal
A2: 46023 | B2: FE-2026-100542 | C2: CL-006 | D2: Ferretería La Campana | E2: Red DAR | F2: Cali | G2: Distribuidor | H2: VD-04 | I2: Felipe Ortiz | J2: Red DAR - Costa | K2: ACC-CAB-LUX | L2: Caballete Luxzo Premium | M2: Accesorios | N2: Accesorios | O2: 127 | P2: und | Q2: 34200 | R2: 0.1 | S2: =O2*Q2 -> 4343400 | T2: =S2*R2 -> 434340 | U2: =S2-T2 -> 3909060 | V2: Mayorista
A3: 46024 | B3: FE-2026-100452 | C3: CL-004 | D3: Homecenter Colombia | E3: Retail | F3: Bogotá | G3: Retail | H3: VD-01 | I3: Carolina Mejía | J3: Cuenta Clave - Centro | K3: LUX-WALL-U | L3: LuxzoWall U - Panel Envolvente | M3: Luxzo | N3: Envolvente Fachada | O3: 233 | P3: m² | Q3: 142000 | R3: 0.05 | S3: =O3*Q3 -> 33086000 | T3: =S3*R3 -> 1654300 | U3: =S3-T3 -> 31431700 | V3: Retail
A4: 46024 | B4: FE-2026-100480 | C4: CL-010 | D4: Distribuidora del Caribe | E4: Red DAR | F4: Barranquilla | G4: Distribuidor | H4: VD-07 | I4: Laura Quintero | J4: Red DAR - Eje Cafetero | K4: TJL-DUR-110 | L4: Teja Duraluz Translúcida 1.1m | M4: Duraluz | N4: Teja Translúcida | O4: 48 | P4: m² | Q4: 52800 | R4: 0.08 | S4: =O4*Q4 -> 2534400 | T4: =S4*R4 -> 202752 | U4: =S4-T4 -> 2331648 | V4: Mayorista
A5: 46024 | B5: FE-2026-100513 | C5: CL-015 | D5: Mario Hincapié Distribuciones | E5: Red DAR | F5: Manizales | G5: Distribuidor | H5: VD-04 | I5: Felipe Ortiz | J5: Red DAR - Costa | K5: ACC-FIJ-KIT | L5: Kit Fijación Tornillería Inox | M5: Accesorios | N5: Accesorios | O5: 125 | P5: kit | Q5: 28500 | R5: 0.1 | S5: =O5*Q5 -> 3562500 | T5: =S5*R5 -> 356250 | U5: =S5-T5 -> 3206250 | V5: Mayorista
A6: 46024 | B6: FE-2026-100529 | C6: CL-004 | D6: Homecenter Colombia | E6: Retail | F6: Bogotá | G6: Retail | H6: VD-02 | I6: Andrés Ramírez | J6: Cuenta Clave - Antioquia | K6: LUX-WALL-D | L6: LuxzoWall D - Panel Envolvente | M6: Luxzo | N6: Envolvente Fachada | O6: 246 | P6: m² | Q6: 156000 | R6: 0.02 | S6: =O6*Q6 -> 38376000 | T6: =S6*R6 -> 767520 | U6: =S6-T6 -> 37608480 | V6: Retail
A7: 46025 | B7: FE-2026-100488 | C7: CL-020 | D7: Coomeva Constructora | E7: Proyecto Directo | F7: Cali | G7: Constructora | H7: VD-06 | I7: Sebastián Gómez | J7: Proyectos - Construcción | K7: ACC-CAB-LUX | L7: Caballete Luxzo Premium | M7: Accesorios | N7: Accesorios | O7: 43 | P7: und | Q7: 34200 | R7: 0 | S7: =O7*Q7 -> 1470600 | T7: =S7*R7 -> 0 | U7: =S7-T7 -> 1470600 | V7: Directo
A8: 46025 | B8: FE-2026-100521 | C8: CL-008 | D8: Industrias Haceb S.A.S. | E8: Proyecto Directo | F8: Medellín | G8: Industrial | H8: VD-05 | I8: Mónica Vélez | J8: Proyectos - Industrial | K8: TJL-TLZ-TRM | L8: Teja Tejaluz Termoselectiva | M8: Tejaluz | N8: Teja Translúcida | O8: 281 | P8: m² | Q8: 96500 | R8: 0.03 | S8: =O8*Q8 -> 27116500 | T8: =S8*R8 -> 813495 | U8: =S8-T8 -> 26303005 | V8: Directo
A9: 46026 | B9: FE-2026-100457 | C9: CL-005 | D9: Centro Comercial Único Bucaramanga | E9: Proyecto Directo | F9: Bucaramanga | G9: Centro Comercial | H9: VD-02 | I9: Andrés Ramírez | J9: Cuenta Clave - Antioquia | K9: LUX-WALL-Z | L9: LuxzoWall Z - Panel Envolvente | M9: Luxzo | N9: Envolvente Fachada | O9: 151 | P9: m² | Q9: 138500 | R9: 0.02 | S9: =O9*Q9 -> 20913500 | T9: =S9*R9 -> 418270 | U9: =S9-T9 -> 20495230 | V9: Directo
A10: 46028 | B10: FE-2026-100503 | C10: CL-017 | D10: Ferretería Tornimax | E10: Red DAR | F10: Bogotá | G10: Distribuidor | H10: VD-04 | I10: Felipe Ortiz | J10: Red DAR - Costa | K10: TJL-DUR-110 | L10: Teja Duraluz Translúcida 1.1m | M10: Duraluz | N10: Teja Translúcida | O10: 57 | P10: m² | Q10: 52800 | R10: 0.1 | S10: =O10*Q10 -> 3009600 | T10: =S10*R10 -> 300960 | U10: =S10-T10 -> 2708640 | V10: Mayorista
A11: 46028 | B11: FE-2026-100508 | C11: CL-019 | D11: Distribuidora Llanos Orientales | E11: Red DAR | F11: Villavicencio | G11: Distribuidor | H11: VD-07 | I11: Laura Quintero | J11: Red DAR - Eje Cafetero | K11: ACC-CAB-LUX | L11: Caballete Luxzo Premium | M11: Accesorios | N11: Accesorios | O11: 159 | P11: und | Q11: 34200 | R11: 0.08 | S11: =O11*Q11 -> 5437800 | T11: =S11*R11 -> 435024 | U11: =S11-T11 -> 5002776 | V11: Mayorista
A12: 46028 | B12: FE-2026-100519 | C12: CL-008 | D12: Industrias Haceb S.A.S. | E12: Proyecto Directo | F12: Medellín | G12: Industrial | H12: VD-05 | I12: Mónica Vélez | J12: Proyectos - Industrial | K12: LAM-PLN-RTF | L12: Lámina Plana Retardante al Fuego | M12: Especial | N12: Lámina Plana | O12: 401 | P12: m² | Q12: 112000 | R12: 0.08 | S12: =O12*Q12 -> 44912000 | T12: =S12*R12 -> 3592960 | U12: =S12-T12 -> 41319040 | V12: Directo
A13: 46030 | B13: FE-2026-100468 | C13: CL-003 | D13: Distribuidora Ferretera Andina | E13: Red DAR | F13: Medellín | G13: Distribuidor | H13: VD-07 | I13: Laura Quintero | J13: Red DAR - Eje Cafetero | K13: TJL-TLZ-OPC | L13: Teja Tejaluz Opaca PRFV | M13: Tejaluz | N13: Teja Opaca | O13: 46 | P13: m² | Q13: 42300 | R13: 0.15 | S13: =O13*Q13 -> 1945800 | T13: =S13*R13 -> 291870 | U13: =S13-T13 -> 1653930 | V13: Mayorista
... A336: 46112 | B336: FE-2026-100732 | C336: CL-009 | D336: Bavaria S.A. - Planta Tocancipá | E336: Proyecto Directo | F336: Tocancipá | G336: Industrial | H336: VD-05 | I336: Mónica Vélez | J336: Proyectos - Industrial | K336: TJL-DUR-110 | L336: Teja Duraluz Translúcida 1.1m | M336: Duraluz | N336: Teja Translúcida | O336: 265 | P336: m² | Q336: 52800 | R336: 0.02 | S336: =O336*Q336 -> 13992000 | T336: =S336*R336 -> 279840 | U336: =S336-T336 -> 13712160 | V336: Directo

Sheet Catálogo Productos
A1: SKU | B1: Producto | C1: Línea | D1: Categoría | E1: Precio Lista (COP) | F1: Unidad
A2: TJL-DUR-090 | B2: Teja Duraluz Translúcida 0.9m | C2: Duraluz | D2: Teja Translúcida | E2: 48500 | F2: m²
A3: TJL-DUR-110 | B3: Teja Duraluz Translúcida 1.1m | C3: Duraluz | D3: Teja Translúcida | E3: 52800 | F3: m²
A4: TJL-GIP-090 | B4: Teja GIP Antigranizo 0.9m | C4: GIP | D4: Teja Antigranizo | E4: 78900 | F4: m²
A5: TJL-GIP-110 | B5: Teja GIP Antigranizo 1.1m | C5: GIP | D5: Teja Antigranizo | E5: 84500 | F5: m²
A6: TJL-TLZ-OPC | B6: Teja Tejaluz Opaca PRFV | C6: Tejaluz | D6: Teja Opaca | E6: 42300 | F6: m²
A7: TJL-TLZ-TRM | B7: Teja Tejaluz Termoselectiva | C7: Tejaluz | D7: Teja Translúcida | E7: 96500 | F7: m²
A8: LUX-WALL-U | B8: LuxzoWall U - Panel Envolvente | C8: Luxzo | D8: Envolvente Fachada | E8: 142000 | F8: m²
A9: LUX-WALL-Z | B9: LuxzoWall Z - Panel Envolvente | C9: Luxzo | D9: Envolvente Fachada | E9: 138500 | F9: m²
A10: LUX-WALL-D | B10: LuxzoWall D - Panel Envolvente | C10: Luxzo | D10: Envolvente Fachada | E10: 156000 | F10: m²
A11: LUX-ROOF-CK | B11: LuxzoRoof Click - Cubierta | C11: Luxzo | D11: Cubierta Premium | E11: 168000 | F11: m²
A12: LAM-PLN-ATV | B12: Lámina Plana Antivirus PRFV | C12: Antivirus | D12: Lámina Plana | E12: 89000 | F12: m²
A13: LAM-PLN-RTF | B13: Lámina Plana Retardante al Fuego | C13: Especial | D13: Lámina Plana | E13: 112000 | F13: m²
... A16: ACC-SLD-UPV | B16: Sellante UPV Profesional | C16: Accesorios | D16: Accesorios | E16: 18900 | F16: und

Sheet Clientes
A1: Código | B1: Cliente | C1: Tipo | D1: Ciudad | E1: Segmento
A2: CL-001 | B2: Constructora Bolívar S.A. | C2: Proyecto Directo | D2: Bogotá | E2: Constructora
A3: CL-002 | B3: Amarilo S.A.S. | C3: Proyecto Directo | D3: Bogotá | E3: Constructora
A4: CL-003 | B4: Distribuidora Ferretera Andina | C4: Red DAR | D4: Medellín | E4: Distribuidor
A5: CL-004 | B5: Homecenter Colombia | C5: Retail | D5: Bogotá | E5: Retail
A6: CL-005 | B6: Centro Comercial Único Bucaramanga | C6: Proyecto Directo | D6: Bucaramanga | E6: Centro Comercial
A7: CL-006 | B7: Ferretería La Campana | C7: Red DAR | D7: Cali | E7: Distribuidor
A8: CL-007 | B8: Conconcreto S.A. | C8: Proyecto Directo | D8: Medellín | E8: Constructora
A9: CL-008 | B9: Industrias Haceb S.A.S. | C9: Proyecto Directo | D9: Medellín | E9: Industrial
A10: CL-009 | B10: Bavaria S.A. - Planta Tocancipá | C10: Proyecto Directo | D10: Tocancipá | E10: Industrial
A11: CL-010 | B11: Distribuidora del Caribe | C11: Red DAR | D11: Barranquilla | E11: Distribuidor
A12: CL-011 | B12: Postobón S.A. - Planta Yumbo | C12: Proyecto Directo | D12: Yumbo | E12: Industrial
... A21: CL-020 | B21: Coomeva Constructora | C21: Proyecto Directo | D21: Cali | E21: Constructora

Sheet Dashboard Q1
A1: EXIPLAST S.A.S. — DASHBOARD COMERCIAL Q1 2026
A2: Período: 01-Ene-2026 al 31-Mar-2026
A4: INDICADORES CLAVE (KPIs)
A5: Indicador | B5: Valor
A6: Ventas Totales (COP) | B6: =SUM('Ventas Q1 2026'!U2:U336) -> 5669882752
A7: Subtotal antes de Descuento (COP) | B7: =SUM('Ventas Q1 2026'!S2:S336) -> 6131878100
A8: Descuentos Otorgados (COP) | B8: =SUM('Ventas Q1 2026'!T2:T336) -> 461995348
A9: % Descuento Promedio | B9: =SUM('Ventas Q1 2026'!T2:T336)/SUM('Ventas Q1 2026'!S2:S336) -> 0.075343205
A10: Cantidad de Facturas | B10: =COUNTA('Ventas Q1 2026'!B2:B336) -> 335
A11: Ticket Promedio (COP) | B11: =SUM('Ventas Q1 2026'!U2:U336)/COUNTA('Ventas Q1 2026'!B2:B336) -> 16925023
A12: Unidades Vendidas (m²/und/kit) | B12: =SUM('Ventas Q1 2026'!O2:O336) -> 79367
A13: Clientes Únicos Atendidos | B13: =SUMPRODUCT(1/COUNTIF('Ventas Q1 2026'!C2:C336,'Ventas Q1 2026'!C2:C336)) -> 20
A16: VENTAS POR MES
A17: Mes | B17: Ventas (COP) | C17: N° Facturas | D17: Ticket Prom. (COP)
A18: Enero 2026 | B18: =SUMIFS('Ventas Q1 2026'!U2:U336,'Ventas Q1 2026'!A2:A336,">="&DATE(2026,1,1),'Ventas Q1 2026'!A2:A336,"<="&DATE(2026,1,31)) -> 1490937770 | C18: =COUNTIFS('Ventas Q1 2026'!A2:A336,">="&DATE(2026,1,1),'Ventas Q1 2026'!A2:A336,"<="&DATE(2026,1,31)) -> 95 | D18: =B18/C18 -> 15694082
A19: Febrero 2026 | B19: =SUMIFS('Ventas Q1 2026'!U2:U336,'Ventas Q1 2026'!A2:A336,">="&DATE(2026,2,1),'Ventas Q1 2026'!A2:A336,"<="&DATE(2026,2,28)) -> 2019252690 | C19: =COUNTIFS('Ventas Q1 2026'!A2:A336,">="&DATE(2026,2,1),'Ventas Q1 2026'!A2:A336,"<="&DATE(2026,2,28)) -> 110 | D19: =B19/C19 -> 18356843
A20: Marzo 2026 | B20: =SUMIFS('Ventas Q1 2026'!U2:U336,'Ventas Q1 2026'!A2:A336,">="&DATE(2026,3,1),'Ventas Q1 2026'!A2:A336,"<="&DATE(2026,3,31)) -> 2159692292 | C20: =COUNTIFS('Ventas Q1 2026'!A2:A336,">="&DATE(2026,3,1),'Ventas Q1 2026'!A2:A336,"<="&DATE(2026,3,31)) -> 130 | D20: =B20/C20 -> 16613018
A21: TOTAL Q1 | B21: =SUM(B18:B20) -> 5669882752 | C21: =SUM(C18:C20) -> 335 | D21: =B21/C21 -> 16925023
A23: TOP 5 PRODUCTOS POR VENTAS
A24: Producto | B24: Ventas (COP) | C24: Unidades
A25: Teja Duraluz Translúcida 1.1m | B25: =SUMIF('Ventas Q1 2026'!L2:L336,A25,'Ventas Q1 2026'!U2:U336) -> 676260816 | C25: =SUMIF('Ventas Q1 2026'!L2:L336,A25,'Ventas Q1 2026'!O2:O336) -> 13851
A26: Lámina Plana Antivirus PRFV | B26: =SUMIF('Ventas Q1 2026'!L2:L336,A26,'Ventas Q1 2026'!U2:U336) -> 612882480 | C26: =SUMIF('Ventas Q1 2026'!L2:L336,A26,'Ventas Q1 2026'!O2:O336) -> 7470
A27: Teja GIP Antigranizo 1.1m | B27: =SUMIF('Ventas Q1 2026'!L2:L336,A27,'Ventas Q1 2026'!U2:U336) -> 550463420 | C27: =SUMIF('Ventas Q1 2026'!L2:L336,A27,'Ventas Q1 2026'!O2:O336) -> 7092
A28: LuxzoWall D - Panel Envolvente | B28: =SUMIF('Ventas Q1 2026'!L2:L336,A28,'Ventas Q1 2026'!U2:U336) -> 535448160 | C28: =SUMIF('Ventas Q1 2026'!L2:L336,A28,'Ventas Q1 2026'!O2:O336) -> 3737
A29: LuxzoRoof Click - Cubierta | B29: =SUMIF('Ventas Q1 2026'!L2:L336,A29,'Ventas Q1 2026'!U2:U336) -> 508658640 | C29: =SUMIF('Ventas Q1 2026'!L2:L336,A29,'Ventas Q1 2026'!O2:O336) -> 3267
A32: TOP 5 CLIENTES POR VENTAS
A33: Cliente | B33: Ventas (COP) | C33: % del Total
A34: Conconcreto S.A. | B34: =SUMIF('Ventas Q1 2026'!D2:D336,A34,'Ventas Q1 2026'!U2:U336) -> 655182222 | C34: =B34/SUM('Ventas Q1 2026'!U2:U336) -> 0.11555481
A35: Industrias Haceb S.A.S. | B35: =SUMIF('Ventas Q1 2026'!D2:D336,A35,'Ventas Q1 2026'!U2:U336) -> 543260958 | C35: =B35/SUM('Ventas Q1 2026'!U2:U336) -> 0.095815201
A36: Cusezar S.A. | B36: =SUMIF('Ventas Q1 2026'!D2:D336,A36,'Ventas Q1 2026'!U2:U336) -> 472219387 | C36: =B36/SUM('Ventas Q1 2026'!U2:U336) -> 0.083285565
A37: Bavaria S.A. - Planta Tocancipá | B37: =SUMIF('Ventas Q1 2026'!D2:D336,A37,'Ventas Q1 2026'!U2:U336) -> 434927488 | C37: =B37/SUM('Ventas Q1 2026'!U2:U336) -> 0.076708374
A38: Homecenter Colombia | B38: =SUMIF('Ventas Q1 2026'!D2:D336,A38,'Ventas Q1 2026'!U2:U336) -> 417579081 | C38: =B38/SUM('Ventas Q1 2026'!U2:U336) -> 0.073648627
A41: VENTAS POR CANAL
A42: Canal | B42: Ventas (COP) | C42: % del Total
A43: Directo | B43: =SUMIF('Ventas Q1 2026'!V2:V336,A43,'Ventas Q1 2026'!U2:U336) -> 4273941231 | C43: =B43/SUM('Ventas Q1 2026'!U2:U336) -> 0.75379711
A44: Mayorista | B44: =SUMIF('Ventas Q1 2026'!V2:V336,A44,'Ventas Q1 2026'!U2:U336) -> 978362440 | C44: =B44/SUM('Ventas Q1 2026'!U2:U336) -> 0.17255426
A45: Retail | B45: =SUMIF('Ventas Q1 2026'!V2:V336,A45,'Ventas Q1 2026'!U2:U336) -> 417579081 | C45: =B45/SUM('Ventas Q1 2026'!U2:U336) -> 0.073648627
A48: VENTAS POR VENDEDOR
A49: Vendedor | B49: Ventas (COP) | C49: N° Facturas | D49: Ticket Prom.
A50: Carolina Mejía | B50: =SUMIF('Ventas Q1 2026'!I2:I336,A50,'Ventas Q1 2026'!U2:U336) -> 427613215 | C50: =COUNTIF('Ventas Q1 2026'!I2:I336,A50) -> 23 | D50: =IFERROR(B50/C50,0) -> 18591879
...
